<?xml version="1.0" encoding="UTF-8"?>
<!-- Generated by org.testng.reporters.JUnitXMLReporter -->
<testsuite ignored="0" hostname="DESKTOP-ST4AN1R" failures="6" tests="35" name="G:/Project/Skyscanner_API" time="26.979" errors="0" timestamp="2024-04-01T10:26:44 BDT">
  <testcase classname="Flights_Indicative_Prices_POST" name="testMissingDestinationPlace" time="2.03"/>
  <testcase classname="Flights_Indicative_Prices_POST" name="testInvalidDateRange" time="0.726"/>
  <testcase classname="Flights_Indicative_Prices_POST" name="testWithoutOptionalParameter" time="1.083"/>
  <testcase classname="Flights_Indicative_Prices_POST" name="testHTTPMethod" time="0.94"/>
  <testcase classname="Flights_Indicative_Prices_POST" name="testUnauthorizedAccess" time="0.52"/>
  <testcase classname="Flights_Indicative_Prices_POST" name="testInvalidURL" time="0.91"/>
  <testcase classname="Flights_Indicative_Prices_POST" name="testInvalidMethod" time="0.637">
    <failure type="java.lang.AssertionError" message="expected [405] but found [501]">
      <![CDATA[java.lang.AssertionError: expected [405] but found [501]
at org.testng.Assert.fail(Assert.java:111)
at org.testng.Assert.failNotEquals(Assert.java:1578)
at org.testng.Assert.assertEqualsImpl(Assert.java:150)
at org.testng.Assert.assertEquals(Assert.java:132)
at org.testng.Assert.assertEquals(Assert.java:1419)
at org.testng.Assert.assertEquals(Assert.java:1383)
at org.testng.Assert.assertEquals(Assert.java:1429)
at Flights_Indicative_Prices_POST.testInvalidMethod(Flights_Indicative_Prices_POST.java:217)
at java.base/jdk.internal.reflect.NativeMethodAccessorImpl.invoke0(Native Method)
at java.base/jdk.internal.reflect.NativeMethodAccessorImpl.invoke(NativeMethodAccessorImpl.java:62)
at java.base/jdk.internal.reflect.DelegatingMethodAccessorImpl.invoke(DelegatingMethodAccessorImpl.java:43)
at java.base/java.lang.reflect.Method.invoke(Method.java:566)
at org.testng.internal.invokers.MethodInvocationHelper.invokeMethod(MethodInvocationHelper.java:139)
at org.testng.internal.invokers.TestInvoker.invokeMethod(TestInvoker.java:664)
at org.testng.internal.invokers.TestInvoker.invokeTestMethod(TestInvoker.java:228)
at org.testng.internal.invokers.MethodRunner.runInSequence(MethodRunner.java:63)
at org.testng.internal.invokers.TestInvoker$MethodInvocationAgent.invoke(TestInvoker.java:961)
at org.testng.internal.invokers.TestInvoker.invokeTestMethods(TestInvoker.java:201)
at org.testng.internal.invokers.TestMethodWorker.invokeTestMethods(TestMethodWorker.java:148)
at org.testng.internal.invokers.TestMethodWorker.run(TestMethodWorker.java:128)
at java.base/java.util.ArrayList.forEach(ArrayList.java:1541)
at org.testng.TestRunner.privateRun(TestRunner.java:819)
at org.testng.TestRunner.run(TestRunner.java:619)
at org.testng.SuiteRunner.runTest(SuiteRunner.java:443)
at org.testng.SuiteRunner.runSequentially(SuiteRunner.java:437)
at org.testng.SuiteRunner.privateRun(SuiteRunner.java:397)
at org.testng.SuiteRunner.run(SuiteRunner.java:336)
at org.testng.SuiteRunnerWorker.runSuite(SuiteRunnerWorker.java:52)
at org.testng.SuiteRunnerWorker.run(SuiteRunnerWorker.java:95)
at org.testng.TestNG.runSuitesSequentially(TestNG.java:1301)
at org.testng.TestNG.runSuitesLocally(TestNG.java:1228)
at org.testng.TestNG.runSuites(TestNG.java:1134)
at org.testng.TestNG.run(TestNG.java:1101)
at com.intellij.rt.testng.IDEARemoteTestNG.run(IDEARemoteTestNG.java:66)
at com.intellij.rt.testng.RemoteTestNGStarter.main(RemoteTestNGStarter.java:105)
]]>
    </failure>
  </testcase> <!-- testInvalidMethod -->
  <testcase classname="Flights_Indicative_Prices_POST" name="testWithInvalidLocale" time="0.611"/>
  <testcase classname="Flights_Indicative_Prices_POST" name="testWithoutMarketParameter" time="0.534"/>
  <testcase classname="Flights_Indicative_Prices_POST" name="testWithoutCurrencyParameter" time="0.606"/>
  <testcase classname="Geo_GET" name="testHTTPMethod" time="2.112"/>
  <testcase classname="Geo_GET" name="testMissingLocale" time="0.683"/>
  <testcase classname="Geo_GET" name="testUnauthorizedAccess" time="0.597"/>
  <testcase classname="Geo_GET" name="testInvalidURL" time="0.612"/>
  <testcase classname="Geo_GET" name="testInvalidMethod" time="0.633">
    <failure type="java.lang.AssertionError" message="1 expectation failed.
Expected status code &amp;lt;405&amp;gt; but was &amp;lt;501&amp;gt;.
">
      <![CDATA[java.lang.AssertionError: 1 expectation failed.
Expected status code <405> but was <501>.

at java.base/jdk.internal.reflect.NativeConstructorAccessorImpl.newInstance0(Native Method)
at java.base/jdk.internal.reflect.NativeConstructorAccessorImpl.newInstance(NativeConstructorAccessorImpl.java:62)
at java.base/jdk.internal.reflect.DelegatingConstructorAccessorImpl.newInstance(DelegatingConstructorAccessorImpl.java:45)
at java.base/java.lang.reflect.Constructor.newInstance(Constructor.java:490)
at org.codehaus.groovy.reflection.CachedConstructor.invoke(CachedConstructor.java:73)
at org.codehaus.groovy.reflection.CachedConstructor.doConstructorInvoke(CachedConstructor.java:60)
at org.codehaus.groovy.runtime.callsite.ConstructorSite$ConstructorSiteNoUnwrap.callConstructor(ConstructorSite.java:86)
at org.codehaus.groovy.runtime.callsite.CallSiteArray.defaultCallConstructor(CallSiteArray.java:57)
at org.codehaus.groovy.runtime.callsite.AbstractCallSite.callConstructor(AbstractCallSite.java:263)
at org.codehaus.groovy.runtime.callsite.AbstractCallSite.callConstructor(AbstractCallSite.java:277)
at io.restassured.internal.ResponseSpecificationImpl$HamcrestAssertionClosure.validate(ResponseSpecificationImpl.groovy:512)
at io.restassured.internal.ResponseSpecificationImpl$HamcrestAssertionClosure$validate$1.call(Unknown Source)
at org.codehaus.groovy.runtime.callsite.CallSiteArray.defaultCall(CallSiteArray.java:45)
at org.codehaus.groovy.runtime.callsite.AbstractCallSite.call(AbstractCallSite.java:125)
at org.codehaus.groovy.runtime.callsite.AbstractCallSite.call(AbstractCallSite.java:139)
at io.restassured.internal.ResponseSpecificationImpl.validateResponseIfRequired(ResponseSpecificationImpl.groovy:696)
at io.restassured.internal.ResponseSpecificationImpl.this$2$validateResponseIfRequired(ResponseSpecificationImpl.groovy)
at java.base/jdk.internal.reflect.NativeMethodAccessorImpl.invoke0(Native Method)
at java.base/jdk.internal.reflect.NativeMethodAccessorImpl.invoke(NativeMethodAccessorImpl.java:62)
at java.base/jdk.internal.reflect.DelegatingMethodAccessorImpl.invoke(DelegatingMethodAccessorImpl.java:43)
at java.base/java.lang.reflect.Method.invoke(Method.java:566)
at org.codehaus.groovy.runtime.callsite.PlainObjectMetaMethodSite.doInvoke(PlainObjectMetaMethodSite.java:43)
at org.codehaus.groovy.runtime.callsite.PogoMetaMethodSite$PogoCachedMethodSiteNoUnwrapNoCoerce.invoke(PogoMetaMethodSite.java:198)
at org.codehaus.groovy.runtime.callsite.PogoMetaMethodSite.callCurrent(PogoMetaMethodSite.java:62)
at org.codehaus.groovy.runtime.callsite.CallSiteArray.defaultCallCurrent(CallSiteArray.java:49)
at org.codehaus.groovy.runtime.callsite.AbstractCallSite.callCurrent(AbstractCallSite.java:171)
at org.codehaus.groovy.runtime.callsite.AbstractCallSite.callCurrent(AbstractCallSite.java:185)
at io.restassured.internal.ResponseSpecificationImpl.statusCode(ResponseSpecificationImpl.groovy:135)
at io.restassured.specification.ResponseSpecification$statusCode$0.callCurrent(Unknown Source)
at org.codehaus.groovy.runtime.callsite.CallSiteArray.defaultCallCurrent(CallSiteArray.java:49)
at org.codehaus.groovy.runtime.callsite.AbstractCallSite.callCurrent(AbstractCallSite.java:171)
at org.codehaus.groovy.runtime.callsite.AbstractCallSite.callCurrent(AbstractCallSite.java:185)
at io.restassured.internal.ResponseSpecificationImpl.statusCode(ResponseSpecificationImpl.groovy:143)
at io.restassured.internal.ValidatableResponseOptionsImpl.statusCode(ValidatableResponseOptionsImpl.java:89)
at Geo_GET.testInvalidMethod(Geo_GET.java:131)
at java.base/jdk.internal.reflect.NativeMethodAccessorImpl.invoke0(Native Method)
at java.base/jdk.internal.reflect.NativeMethodAccessorImpl.invoke(NativeMethodAccessorImpl.java:62)
at java.base/jdk.internal.reflect.DelegatingMethodAccessorImpl.invoke(DelegatingMethodAccessorImpl.java:43)
at java.base/java.lang.reflect.Method.invoke(Method.java:566)
at org.testng.internal.invokers.MethodInvocationHelper.invokeMethod(MethodInvocationHelper.java:139)
at org.testng.internal.invokers.TestInvoker.invokeMethod(TestInvoker.java:664)
at org.testng.internal.invokers.TestInvoker.invokeTestMethod(TestInvoker.java:228)
at org.testng.internal.invokers.MethodRunner.runInSequence(MethodRunner.java:63)
at org.testng.internal.invokers.TestInvoker$MethodInvocationAgent.invoke(TestInvoker.java:961)
at org.testng.internal.invokers.TestInvoker.invokeTestMethods(TestInvoker.java:201)
at org.testng.internal.invokers.TestMethodWorker.invokeTestMethods(TestMethodWorker.java:148)
at org.testng.internal.invokers.TestMethodWorker.run(TestMethodWorker.java:128)
at java.base/java.util.ArrayList.forEach(ArrayList.java:1541)
at org.testng.TestRunner.privateRun(TestRunner.java:819)
at org.testng.TestRunner.run(TestRunner.java:619)
at org.testng.SuiteRunner.runTest(SuiteRunner.java:443)
at org.testng.SuiteRunner.runSequentially(SuiteRunner.java:437)
at org.testng.SuiteRunner.privateRun(SuiteRunner.java:397)
at org.testng.SuiteRunner.run(SuiteRunner.java:336)
at org.testng.SuiteRunnerWorker.runSuite(SuiteRunnerWorker.java:52)
at org.testng.SuiteRunnerWorker.run(SuiteRunnerWorker.java:95)
at org.testng.TestNG.runSuitesSequentially(TestNG.java:1301)
at org.testng.TestNG.runSuitesLocally(TestNG.java:1228)
at org.testng.TestNG.runSuites(TestNG.java:1134)
at org.testng.TestNG.run(TestNG.java:1101)
at com.intellij.rt.testng.IDEARemoteTestNG.run(IDEARemoteTestNG.java:66)
at com.intellij.rt.testng.RemoteTestNGStarter.main(RemoteTestNGStarter.java:105)
]]>
    </failure>
  </testcase> <!-- testInvalidMethod -->
  <testcase classname="Geo_POST" name="testInvalidIpAddress" time="0.403"/>
  <testcase classname="Geo_POST" name="testAdditionalField" time="0.763"/>
  <testcase classname="Geo_POST" name="testUnauthorizedAccess" time="0.625"/>
  <testcase classname="Geo_POST" name="testHTTPMethod" time="0.517"/>
  <testcase classname="Geo_POST" name="testInvalidURL" time="0.586"/>
  <testcase classname="Geo_POST" name="testInvalidMethod" time="0.485">
    <failure type="java.lang.AssertionError" message="expected [405] but found [501]">
      <![CDATA[java.lang.AssertionError: expected [405] but found [501]
at org.testng.Assert.fail(Assert.java:111)
at org.testng.Assert.failNotEquals(Assert.java:1578)
at org.testng.Assert.assertEqualsImpl(Assert.java:150)
at org.testng.Assert.assertEquals(Assert.java:132)
at org.testng.Assert.assertEquals(Assert.java:1419)
at org.testng.Assert.assertEquals(Assert.java:1383)
at org.testng.Assert.assertEquals(Assert.java:1429)
at Geo_POST.testInvalidMethod(Geo_POST.java:185)
at java.base/jdk.internal.reflect.NativeMethodAccessorImpl.invoke0(Native Method)
at java.base/jdk.internal.reflect.NativeMethodAccessorImpl.invoke(NativeMethodAccessorImpl.java:62)
at java.base/jdk.internal.reflect.DelegatingMethodAccessorImpl.invoke(DelegatingMethodAccessorImpl.java:43)
at java.base/java.lang.reflect.Method.invoke(Method.java:566)
at org.testng.internal.invokers.MethodInvocationHelper.invokeMethod(MethodInvocationHelper.java:139)
at org.testng.internal.invokers.TestInvoker.invokeMethod(TestInvoker.java:664)
at org.testng.internal.invokers.TestInvoker.invokeTestMethod(TestInvoker.java:228)
at org.testng.internal.invokers.MethodRunner.runInSequence(MethodRunner.java:63)
at org.testng.internal.invokers.TestInvoker$MethodInvocationAgent.invoke(TestInvoker.java:961)
at org.testng.internal.invokers.TestInvoker.invokeTestMethods(TestInvoker.java:201)
at org.testng.internal.invokers.TestMethodWorker.invokeTestMethods(TestMethodWorker.java:148)
at org.testng.internal.invokers.TestMethodWorker.run(TestMethodWorker.java:128)
at java.base/java.util.ArrayList.forEach(ArrayList.java:1541)
at org.testng.TestRunner.privateRun(TestRunner.java:819)
at org.testng.TestRunner.run(TestRunner.java:619)
at org.testng.SuiteRunner.runTest(SuiteRunner.java:443)
at org.testng.SuiteRunner.runSequentially(SuiteRunner.java:437)
at org.testng.SuiteRunner.privateRun(SuiteRunner.java:397)
at org.testng.SuiteRunner.run(SuiteRunner.java:336)
at org.testng.SuiteRunnerWorker.runSuite(SuiteRunnerWorker.java:52)
at org.testng.SuiteRunnerWorker.run(SuiteRunnerWorker.java:95)
at org.testng.TestNG.runSuitesSequentially(TestNG.java:1301)
at org.testng.TestNG.runSuitesLocally(TestNG.java:1228)
at org.testng.TestNG.runSuites(TestNG.java:1134)
at org.testng.TestNG.run(TestNG.java:1101)
at com.intellij.rt.testng.IDEARemoteTestNG.run(IDEARemoteTestNG.java:66)
at com.intellij.rt.testng.RemoteTestNGStarter.main(RemoteTestNGStarter.java:105)
]]>
    </failure>
  </testcase> <!-- testInvalidMethod -->
  <testcase classname="Geo_POST" name="testInvalidLocale" time="0.43"/>
  <testcase classname="Autosuggest_POST" name="testHTTPMethod" time="0.55"/>
  <testcase classname="Autosuggest_POST" name="testInvalidSearchTerm" time="0.645"/>
  <testcase classname="Autosuggest_POST" name="testInvalidMethod" time="0.413"/>
  <testcase classname="Autosuggest_POST" name="testUnauthorizedAccess" time="0.802"/>
  <testcase classname="Autosuggest_POST" name="testInvalidURL" time="0.457"/>
  <testcase classname="Autosuggest_POST" name="testExeceedingLimit" time="0.679">
    <failure type="java.lang.AssertionError" message="expected [400] but found [422]">
      <![CDATA[java.lang.AssertionError: expected [400] but found [422]
at org.testng.Assert.fail(Assert.java:111)
at org.testng.Assert.failNotEquals(Assert.java:1578)
at org.testng.Assert.assertEqualsImpl(Assert.java:150)
at org.testng.Assert.assertEquals(Assert.java:132)
at org.testng.Assert.assertEquals(Assert.java:1419)
at org.testng.Assert.assertEquals(Assert.java:1383)
at org.testng.Assert.assertEquals(Assert.java:1429)
at Autosuggest_POST.testExeceedingLimit(Autosuggest_POST.java:194)
at java.base/jdk.internal.reflect.NativeMethodAccessorImpl.invoke0(Native Method)
at java.base/jdk.internal.reflect.NativeMethodAccessorImpl.invoke(NativeMethodAccessorImpl.java:62)
at java.base/jdk.internal.reflect.DelegatingMethodAccessorImpl.invoke(DelegatingMethodAccessorImpl.java:43)
at java.base/java.lang.reflect.Method.invoke(Method.java:566)
at org.testng.internal.invokers.MethodInvocationHelper.invokeMethod(MethodInvocationHelper.java:139)
at org.testng.internal.invokers.TestInvoker.invokeMethod(TestInvoker.java:664)
at org.testng.internal.invokers.TestInvoker.invokeTestMethod(TestInvoker.java:228)
at org.testng.internal.invokers.MethodRunner.runInSequence(MethodRunner.java:63)
at org.testng.internal.invokers.TestInvoker$MethodInvocationAgent.invoke(TestInvoker.java:961)
at org.testng.internal.invokers.TestInvoker.invokeTestMethods(TestInvoker.java:201)
at org.testng.internal.invokers.TestMethodWorker.invokeTestMethods(TestMethodWorker.java:148)
at org.testng.internal.invokers.TestMethodWorker.run(TestMethodWorker.java:128)
at java.base/java.util.ArrayList.forEach(ArrayList.java:1541)
at org.testng.TestRunner.privateRun(TestRunner.java:819)
at org.testng.TestRunner.run(TestRunner.java:619)
at org.testng.SuiteRunner.runTest(SuiteRunner.java:443)
at org.testng.SuiteRunner.runSequentially(SuiteRunner.java:437)
at org.testng.SuiteRunner.privateRun(SuiteRunner.java:397)
at org.testng.SuiteRunner.run(SuiteRunner.java:336)
at org.testng.SuiteRunnerWorker.runSuite(SuiteRunnerWorker.java:52)
at org.testng.SuiteRunnerWorker.run(SuiteRunnerWorker.java:95)
at org.testng.TestNG.runSuitesSequentially(TestNG.java:1301)
at org.testng.TestNG.runSuitesLocally(TestNG.java:1228)
at org.testng.TestNG.runSuites(TestNG.java:1134)
at org.testng.TestNG.run(TestNG.java:1101)
at com.intellij.rt.testng.IDEARemoteTestNG.run(IDEARemoteTestNG.java:66)
at com.intellij.rt.testng.RemoteTestNGStarter.main(RemoteTestNGStarter.java:105)
]]>
    </failure>
  </testcase> <!-- testExeceedingLimit -->
  <testcase classname="Autosuggest_POST" name="testInvalidLocale" time="0.548"/>
  <testcase classname="Autosuggest_POST" name="testMissingMarket" time="0.539">
    <failure type="java.lang.AssertionError" message="expected [400] but found [422]">
      <![CDATA[java.lang.AssertionError: expected [400] but found [422]
at org.testng.Assert.fail(Assert.java:111)
at org.testng.Assert.failNotEquals(Assert.java:1578)
at org.testng.Assert.assertEqualsImpl(Assert.java:150)
at org.testng.Assert.assertEquals(Assert.java:132)
at org.testng.Assert.assertEquals(Assert.java:1419)
at org.testng.Assert.assertEquals(Assert.java:1383)
at org.testng.Assert.assertEquals(Assert.java:1429)
at Autosuggest_POST.testMissingMarket(Autosuggest_POST.java:248)
at java.base/jdk.internal.reflect.NativeMethodAccessorImpl.invoke0(Native Method)
at java.base/jdk.internal.reflect.NativeMethodAccessorImpl.invoke(NativeMethodAccessorImpl.java:62)
at java.base/jdk.internal.reflect.DelegatingMethodAccessorImpl.invoke(DelegatingMethodAccessorImpl.java:43)
at java.base/java.lang.reflect.Method.invoke(Method.java:566)
at org.testng.internal.invokers.MethodInvocationHelper.invokeMethod(MethodInvocationHelper.java:139)
at org.testng.internal.invokers.TestInvoker.invokeMethod(TestInvoker.java:664)
at org.testng.internal.invokers.TestInvoker.invokeTestMethod(TestInvoker.java:228)
at org.testng.internal.invokers.MethodRunner.runInSequence(MethodRunner.java:63)
at org.testng.internal.invokers.TestInvoker$MethodInvocationAgent.invoke(TestInvoker.java:961)
at org.testng.internal.invokers.TestInvoker.invokeTestMethods(TestInvoker.java:201)
at org.testng.internal.invokers.TestMethodWorker.invokeTestMethods(TestMethodWorker.java:148)
at org.testng.internal.invokers.TestMethodWorker.run(TestMethodWorker.java:128)
at java.base/java.util.ArrayList.forEach(ArrayList.java:1541)
at org.testng.TestRunner.privateRun(TestRunner.java:819)
at org.testng.TestRunner.run(TestRunner.java:619)
at org.testng.SuiteRunner.runTest(SuiteRunner.java:443)
at org.testng.SuiteRunner.runSequentially(SuiteRunner.java:437)
at org.testng.SuiteRunner.privateRun(SuiteRunner.java:397)
at org.testng.SuiteRunner.run(SuiteRunner.java:336)
at org.testng.SuiteRunnerWorker.runSuite(SuiteRunnerWorker.java:52)
at org.testng.SuiteRunnerWorker.run(SuiteRunnerWorker.java:95)
at org.testng.TestNG.runSuitesSequentially(TestNG.java:1301)
at org.testng.TestNG.runSuitesLocally(TestNG.java:1228)
at org.testng.TestNG.runSuites(TestNG.java:1134)
at org.testng.TestNG.run(TestNG.java:1101)
at com.intellij.rt.testng.IDEARemoteTestNG.run(IDEARemoteTestNG.java:66)
at com.intellij.rt.testng.RemoteTestNGStarter.main(RemoteTestNGStarter.java:105)
]]>
    </failure>
  </testcase> <!-- testMissingMarket -->
  <testcase classname="Carriers_GET" name="testUnauthorizedAccess" time="0.946"/>
  <testcase classname="Carriers_GET" name="testInvalidURL" time="0.614"/>
  <testcase classname="Carriers_GET" name="testContentValidation" time="1.831"/>
  <testcase classname="Carriers_GET" name="testHTTPMethod" time="0.647"/>
  <testcase classname="Carriers_GET" name="testInvalidMethod" time="0.561">
    <failure type="java.lang.AssertionError" message="expected [405] but found [501]">
      <![CDATA[java.lang.AssertionError: expected [405] but found [501]
at org.testng.Assert.fail(Assert.java:111)
at org.testng.Assert.failNotEquals(Assert.java:1578)
at org.testng.Assert.assertEqualsImpl(Assert.java:150)
at org.testng.Assert.assertEquals(Assert.java:132)
at org.testng.Assert.assertEquals(Assert.java:1419)
at org.testng.Assert.assertEquals(Assert.java:1383)
at org.testng.Assert.assertEquals(Assert.java:1429)
at Carriers_GET.testInvalidMethod(Carriers_GET.java:136)
at java.base/jdk.internal.reflect.NativeMethodAccessorImpl.invoke0(Native Method)
at java.base/jdk.internal.reflect.NativeMethodAccessorImpl.invoke(NativeMethodAccessorImpl.java:62)
at java.base/jdk.internal.reflect.DelegatingMethodAccessorImpl.invoke(DelegatingMethodAccessorImpl.java:43)
at java.base/java.lang.reflect.Method.invoke(Method.java:566)
at org.testng.internal.invokers.MethodInvocationHelper.invokeMethod(MethodInvocationHelper.java:139)
at org.testng.internal.invokers.TestInvoker.invokeMethod(TestInvoker.java:664)
at org.testng.internal.invokers.TestInvoker.invokeTestMethod(TestInvoker.java:228)
at org.testng.internal.invokers.MethodRunner.runInSequence(MethodRunner.java:63)
at org.testng.internal.invokers.TestInvoker$MethodInvocationAgent.invoke(TestInvoker.java:961)
at org.testng.internal.invokers.TestInvoker.invokeTestMethods(TestInvoker.java:201)
at org.testng.internal.invokers.TestMethodWorker.invokeTestMethods(TestMethodWorker.java:148)
at org.testng.internal.invokers.TestMethodWorker.run(TestMethodWorker.java:128)
at java.base/java.util.ArrayList.forEach(ArrayList.java:1541)
at org.testng.TestRunner.privateRun(TestRunner.java:819)
at org.testng.TestRunner.run(TestRunner.java:619)
at org.testng.SuiteRunner.runTest(SuiteRunner.java:443)
at org.testng.SuiteRunner.runSequentially(SuiteRunner.java:437)
at org.testng.SuiteRunner.privateRun(SuiteRunner.java:397)
at org.testng.SuiteRunner.run(SuiteRunner.java:336)
at org.testng.SuiteRunnerWorker.runSuite(SuiteRunnerWorker.java:52)
at org.testng.SuiteRunnerWorker.run(SuiteRunnerWorker.java:95)
at org.testng.TestNG.runSuitesSequentially(TestNG.java:1301)
at org.testng.TestNG.runSuitesLocally(TestNG.java:1228)
at org.testng.TestNG.runSuites(TestNG.java:1134)
at org.testng.TestNG.run(TestNG.java:1101)
at com.intellij.rt.testng.IDEARemoteTestNG.run(IDEARemoteTestNG.java:66)
at com.intellij.rt.testng.RemoteTestNGStarter.main(RemoteTestNGStarter.java:105)
]]>
    </failure>
  </testcase> <!-- testInvalidMethod -->
</testsuite> <!-- G:/Project/Skyscanner_API -->
